Workbook

Sheet Diagrama_Gantt_WBS
A1: COLIVI TFG - DIAGRAMA DE GANTT (CRONOGRAMA WBS EJECUTADO)
A2: Consolidacion temporal objetiva del proyecto basada en 42 Pull Requests aprobadas y 12 modulos funcionales.
A4: VENTANA TEMPORAL 01/06/2026 - 21/09/2026 (113 Dias) | D4: ALCANCE WBS 12 Modulos Funcionales (100% Completados) | G4: AUDITORIA GIT 42 Pull Requests Aprobadas
A6: WBS | B6: Modulo Funcional | C6: Fecha Inicio | D6: Fecha Fin | E6: Duracion (Dias) | F6: No PRs | G6: Estado
A7: =Gantt_y_Comparativa!A7 -> F01 | B7: =Gantt_y_Comparativa!A7 & ": " & Gantt_y_Comparativa!B7 -> F01: Arquitectura Base, Infraestructura y DevOps | C7: =Gantt_y_Comparativa!D7 -> 46174 | D7: =Gantt_y_Comparativa!E7 -> 46264 | E7: =Gantt_y_Comparativa!F7 -> 91 | F7: =Gantt_y_Comparativa!G7 -> 6 | G7: =Gantt_y_Comparativa!I7 -> Completado
A8: =Gantt_y_Comparativa!A8 -> F02 | B8: =Gantt_y_Comparativa!A8 & ": " & Gantt_y_Comparativa!B8 -> F02: Gestión de Usuarios, Autenticación y Perfiles | C8: =Gantt_y_Comparativa!D8 -> 46201 | D8: =Gantt_y_Comparativa!E8 -> 46269 | E8: =Gantt_y_Comparativa!F8 -> 69 | F8: =Gantt_y_Comparativa!G8 -> 10 | G8: =Gantt_y_Comparativa!I8 -> Completado
A9: =Gantt_y_Comparativa!A9 -> F03 | B9: =Gantt_y_Comparativa!A9 & ": " & Gantt_y_Comparativa!B9 -> F03: Gestión de Alojamientos y Catálogo | C9: =Gantt_y_Comparativa!D9 -> 46208 | D9: =Gantt_y_Comparativa!E9 -> 46264 | E9: =Gantt_y_Comparativa!F9 -> 57 | F9: =Gantt_y_Comparativa!G9 -> 6 | G9: =Gantt_y_Comparativa!I9 -> Completado
A10: =Gantt_y_Comparativa!A10 -> F04 | B10: =Gantt_y_Comparativa!A10 & ": " & Gantt_y_Comparativa!B10 -> F04: Solicitudes de Reserva y Pagos de Fianza | C10: =Gantt_y_Comparativa!D10 -> 46216 | D10: =Gantt_y_Comparativa!E10 -> 46264 | E10: =Gantt_y_Comparativa!F10 -> 49 | F10: =Gantt_y_Comparativa!G10 -> 5 | G10: =Gantt_y_Comparativa!I10 -> Completado
A11: =Gantt_y_Comparativa!A11 -> F05 | B11: =Gantt_y_Comparativa!A11 & ": " & Gantt_y_Comparativa!B11 -> F05: Gestión de Hogares y Convivencia | C11: =Gantt_y_Comparativa!D11 -> 46234 | D11: =Gantt_y_Comparativa!E11 -> 46268 | E11: =Gantt_y_Comparativa!F11 -> 35 | F11: =Gantt_y_Comparativa!G11 -> 3 | G11: =Gantt_y_Comparativa!I11 -> Completado
A12: =Gantt_y_Comparativa!A12 -> F06 | B12: =Gantt_y_Comparativa!A12 & ": " & Gantt_y_Comparativa!B12 -> F06: Gestión de Gastos Compartidos (Expenses) | C12: =Gantt_y_Comparativa!D12 -> 46241 | D12: =Gantt_y_Comparativa!E12 -> 46268 | E12: =Gantt_y_Comparativa!F12 -> 28 | F12: =Gantt_y_Comparativa!G12 -> 2 | G12: =Gantt_y_Comparativa!I12 -> Completado
A13: =Gantt_y_Comparativa!A13 -> F07 | B13: =Gantt_y_Comparativa!A13 & ": " & Gantt_y_Comparativa!B13 -> F07: Sistema de Denuncias, Reseñas y Moderación | C13: =Gantt_y_Comparativa!D13 -> 46243 | D13: =Gantt_y_Comparativa!E13 -> 46267 | E13: =Gantt_y_Comparativa!F13 -> 25 | F13: =Gantt_y_Comparativa!G13 -> 4 | G13: =Gantt_y_Comparativa!I13 -> Completado
A14: =Gantt_y_Comparativa!A14 -> F08 | B14: =Gantt_y_Comparativa!A14 & ": " & Gantt_y_Comparativa!B14 -> F08: Tareas Domésticas y Gamificación (Chores) | C14: =Gantt_y_Comparativa!D14 -> 46271 | D14: =Gantt_y_Comparativa!E14 -> 46271 | E14: =Gantt_y_Comparativa!F14 -> 1 | F14: =Gantt_y_Comparativa!G14 -> 1 | G14: =Gantt_y_Comparativa!I14 -> Completado
A15: =Gantt_y_Comparativa!A15 -> F09 | B15: =Gantt_y_Comparativa!A15 & ": " & Gantt_y_Comparativa!B15 -> F09: Sistema de Mensajería Interna | C15: =Gantt_y_Comparativa!D15 -> 46272 | D15: =Gantt_y_Comparativa!E15 -> 46273 | E15: =Gantt_y_Comparativa!F15 -> 2 | F15: =Gantt_y_Comparativa!G15 -> 1 | G15: =Gantt_y_Comparativa!I15 -> Completado
A16: =Gantt_y_Comparativa!A16 -> F10 | B16: =Gantt_y_Comparativa!A16 & ": " & Gantt_y_Comparativa!B16 -> F10: Asistente Virtual Inteligente (IA & MCP) | C16: =Gantt_y_Comparativa!D16 -> 46275 | D16: =Gantt_y_Comparativa!E16 -> 46277 | E16: =Gantt_y_Comparativa!F16 -> 3 | F16: =Gantt_y_Comparativa!G16 -> 1 | G16: =Gantt_y_Comparativa!I16 -> Completado
A17: =Gantt_y_Comparativa!A17 -> F11 | B17: =Gantt_y_Comparativa!A17 & ": " & Gantt_y_Comparativa!B17 -> F11: Adaptabilidad Móvil y Despliegue Android | C17: =Gantt_y_Comparativa!D17 -> 46282 | D17: =Gantt_y_Comparativa!E17 -> 46286 | E17: =Gantt_y_Comparativa!F17 -> 5 | F17: =Gantt_y_Comparativa!G17 -> 2 | G17: =Gantt_y_Comparativa!I17 -> Completado
A18: =Gantt_y_Comparativa!A18 -> F12 | B18: =Gantt_y_Comparativa!A18 & ": " & Gantt_y_Comparativa!B18 -> F12: Cumplimiento Legal y Privacidad (RGPD) | C18: =Gantt_y_Comparativa!D18 -> 46286 | D18: =Gantt_y_Comparativa!E18 -> 46286 | E18: =Gantt_y_Comparativa!F18 -> 1 | F18: =Gantt_y_Comparativa!G18 -> 1 | G18: =Gantt_y_Comparativa!I18 -> Completado
A19: TOTAL | B19: 12 Modulos Funcionales | C19: =MIN(C7:C18) -> 46174 | D19: =MAX(D7:D18) -> 46286 | E19: =D19-C19+1 -> 113 | F19: =SUM(F7:F18) -> 42 | G19: 1

Sheet Gantt_y_Comparativa
A1: COLIVI TFG - CRONOGRAMA INTEGRAL, ESTIMACIÓN INICIAL Y ANÁLISIS DE DESVIACIONES
A2: Consolidación en una sola vista del WBS ejecutado (12 módulos, 42 PRs), plan teórico (CLAUDE.md), matriz comparativa y justificaciones metodológicas del TFG.
A4: SECCIÓN 1: CRONOGRAMA REAL EJECUTADO POR MÓDULOS FUNCIONALES (WBS)
J5: JUNIO 2026 | O5: JULIO 2026 | S5: AGOSTO 2026 | X5: SEPTIEMBRE 2026
A6: Código WBS | B6: Módulo Funcional | C6: Alcance y Entregables Clave | D6: Fecha Inicio | E6: Fecha Fin | F6: Duración (Días) | G6: Nº PRs | H6: PRs Asociadas | I6: Estado | J6: S1 (01/06) | K6: S2 (08/06) | L6: S3 (15/06) | M6: S4 (22/06) | N6: S5 (29/06) | O6: S6 (06/07) | P6: S7 (13/07) | Q6: S8 (20/07) | R6: S9 (27/07) | S6: S10 (03/08) | T6: S11 (10/08) | U6: S12 (17/08) | V6: S13 (24/08) | W6: S14 (31/08) | X6: S15 (07/09) | Y6: S16 (14/09) | Z6: S17 (21/09) | AA6: S18 (28/09)
A7: F01 | B7: Arquitectura Base, Infraestructura y DevOps | C7: Configuración de repositorio, pipelines CI/CD, Docker Compose, desacoplamiento SOLID y arquitectura limpia. | D7: 46174 | E7: 46264 | F7: =E7-D7+1 -> 91 | G7: 6 | H7: #1, #28, #35, #37, #41, #52 | I7: Completado | J7: [====] | K7: [====] | L7: [====] | M7: [====] | N7: [====] | O7: [====] | P7: [====] | Q7: [====] | R7: [====] | S7: [====] | T7: [====] | U7: [====] | V7: [====]
A8: F02 | B8: Gestión de Usuarios, Autenticación y Perfiles | C8: Autenticación stateless JWT, OAuth2 con Google, recuperación de contraseña, perfiles de usuario y borrado lógico. | D8: 46201 | E8: 46269 | F8: =E8-D8+1 -> 69 | G8: 10 | H8: #2, #3, #30, #31, #43, #46, #47, #48, #54, #60 | I8: Completado | M8: [====] | N8: [====] | O8: [====] | P8: [====] | Q8: [====] | R8: [====] | S8: [====] | T8: [====] | U8: [====] | V8: [====] | W8: [====]
A9: F03 | B9: Gestión de Alojamientos y Catálogo | C9: Publicación de inmuebles, catálogo de comodidades para coliving, filtros avanzados, mapas interactivos y recomendador. | D9: 46208 | E9: 46264 | F9: =E9-D9+1 -> 57 | G9: 6 | H9: #29, #33, #45, #49, #50, #55 | I9: Completado | N9: [====] | O9: [====] | P9: [====] | Q9: [====] | R9: [====] | S9: [====] | T9: [====] | U9: [====] | V9: [====]
A10: F04 | B10: Solicitudes de Reserva y Pagos de Fianza | C10: Ciclo de reservas de estancia, validación de meses completos, control de concurrencia, deep-linking y depósito de fianza. | D10: 46216 | E10: 46264 | F10: =E10-D10+1 -> 49 | G10: 5 | H10: #32, #34, #36, #44, #51 | I10: Completado | P10: [====] | Q10: [====] | R10: [====] | S10: [====] | T10: [====] | U10: [====] | V10: [====]
A11: F05 | B11: Gestión de Hogares y Convivencia | C11: Administración de unidades de convivencia (Hogares), asignación de inquilinos y registro cronológico de actividad. | D11: 46234 | E11: 46268 | F11: =E11-D11+1 -> 35 | G11: 3 | H11: #38, #40, #58 | I11: Completado | R11: [====] | S11: [====] | T11: [====] | U11: [====] | V11: [====] | W11: [====]
A12: F06 | B12: Gestión de Gastos Compartidos (Expenses) | C12: Reparto proporcional de gastos comunes, cálculo dinámico de deudas, liquidación de saldos y auditoría contable. | D12: 46241 | E12: 46268 | F12: =E12-D12+1 -> 28 | G12: 2 | H12: #39, #59 | I12: Completado | S12: [====] | T12: [====] | U12: [====] | V12: [====] | W12: [====]
A13: F07 | B13: Sistema de Denuncias, Reseñas y Moderación | C13: Canal de reporte de incidencias, valoraciones verificadas, ranking de moderación y resolución administrativa en cascada. | D13: 46243 | E13: 46267 | F13: =E13-D13+1 -> 25 | G13: 4 | H13: #42, #53, #56, #57 | I13: Completado | S13: [====] | T13: [====] | U13: [====] | V13: [====] | W13: [====]
A14: F08 | B14: Tareas Domésticas y Gamificación (Chores) | C14: Asignación rotativa automatizada de tareas (round-robin), periodicidad recurrente y tabla de puntuación (leaderboard). | D14: 46271 | E14: 46271 | F14: =E14-D14+1 -> 1 | G14: 1 | H14: #61 | I14: Completado | W14: [====]
A15: F09 | B15: Sistema de Mensajería Interna | C15: Canal de mensajería privada entre miembros y propietarios, persistencia de chats e integración con reportes. | D15: 46272 | E15: 46273 | F15: =E15-D15+1 -> 2 | G15: 1 | H15: #62 | I15: Completado | X15: [====]
A16: F10 | B16: Asistente Virtual Inteligente (IA & MCP) | C16: Integración de Spring AI con Model Context Protocol (MCP), orquestación de herramientas y widget React Copilot. | D16: 46275 | E16: 46277 | F16: =E16-D16+1 -> 3 | G16: 1 | H16: #63 | I16: Completado | X16: [====]
A17: F11 | B17: Adaptabilidad Móvil y Despliegue Android | C17: Optimización ergonómica responsive para móviles, integración con Capacitor y empaquetado del APK de Android. | D17: 46282 | E17: 46286 | F17: =E17-D17+1 -> 5 | G17: 2 | H17: #64, #65 | I17: Completado | Y17: [====] | Z17: [====]
A18: F12 | B18: Cumplimiento Legal y Privacidad (RGPD) | C18: Plataforma de gestión de consentimiento (CMP), políticas de privacidad, términos legales y adaptación LOPDGDD. | D18: 46286 | E18: 46286 | F18: =E18-D18+1 -> 1 | G18: 1 | H18: #66 | I18: Completado | Z18: [====]
A19: TOTALES | B19: 12 Módulos Funcionales | C19: Cobertura funcional integral del proyecto | D19: 2026-06-01 | E19: 2026-09-21 | F19: 113 | G19: =SUM(G7:G18) -> 42 | H19: 42 PRs Aprobadas | I19: 100%
A22: SECCIÓN 2: ESTIMACIÓN INICIAL DE TIEMPOS (PLAN MAESTRO CLAUDE.MD) | J22: CRONOGRAMA TEÓRICO ESTIMADO (SEMANAS 0 A 9)
A23: Fase | B23: Nombre de la Fase | C23: Objetivo y Entregable Verificable | D23: Ventana Estimada | E23: Módulo Principal | F23: Duración (Sem.) | G23: Nº Tareas | H23: Metodología / SOLID | I23: Módulo Real (WBS) | J23: Sem 0 | K23: Sem 1 | L23: Sem 2 | M23: Sem 3 | N23: Sem 4 | O23: Sem 5 | P23: Sem 6 | Q23: Sem 7 | R23: Sem 8 | S23: Sem 9
A24: Fase 0 | B24: Configuración del Entorno y Scaffolding | C24: Objetivo: Tener un entorno de desarrollo funcional con todas las herramientas configuradas antes de escribir una sola línea de lógica. | Entregable: docker-compose up levanta PostgreSQL, backend arranca con 200 OK en /api/v1/health, frontend carga en localhost:3000. | D24: Semana 0 | E24: Scaffolding, Docker, esquema BD | F24: 1 | G24: 9 | H24: Monorepo modular, Docker Compose, Flyway V1__init_schema. | I24: F01 (Arquitectura | J24: [====]
A25: Fase 1 | B25: Núcleo de Seguridad y Gestión de Usuarios | C25: Objetivo: Sistema de autenticación robusto y gestión de perfiles de usuario. | Entregable: Un usuario puede registrarse, iniciar sesión y obtener su perfil con token JWT válido. Intentos erróneos devuelven 401. | D25: Semanas 1-2 | E25: Autenticación JWT y gestión de usuarios | F25: 2 | G25: 15 | H25: SRP (IUserService, ITokenProvider), DIP (SecurityConfig desacoplado de la implementación). | I25: F02 (Gestión de Us | K25: [====] | L25: [====]
A26: Fase 2 | B26: Motor Financiero (TDD Obligatorio) | C26: Objetivo: Implementar el núcleo del módulo de gastos compartidos con cobertura de tests completa antes de escribir el código de producción. | Entregable: Cobertura tests > 90 % en clases financieras. Endpoint de balances devuelve el grafo de deudas simplificado. | D26: Semanas 3-4 | E26: Motor financiero (TDD) — Gastos y deudas | F26: 2 | G26: 23 | H26: TDD estricto (Red-Green-Refactor), OCP (DebtSimplifierEngine intercambiable), SRP (ExpenseService). | I26: F06 (Gestión de Ga | M26: [====] | N26: [====]
A27: Fase 3 | B27: Subsistema de Auditoría e Inmutabilidad | C27: Objetivo: Implementar la capa de trazabilidad append-only con captura automática de snapshots JSONB. | Entregable: Cualquier mutación sobre EXPENSE o TASK genera snapshot inmutable. Feed de actividad cronológico funcional. | D27: Semana 5 | E27: Auditoría inmutable y feed de actividad | F27: 1 | G27: 13 | H27: SRP (IAuditService), ISP (AuditLogRepository append-only sin delete/update), DIP (listeners JPA y trigger PostgreSQL). | I27: F05 (Gestión de Ho | O27: [====]
A28: Fase 4 | B28: Módulo de Alojamiento: Estructura Física e Imágenes | C28: Objetivo: Implementar la base de datos de las propiedades físicas (Accommodation) y la integración de almacenamiento cloud en Cloudinary. | Entregable: Un propietario autenticado puede registrar su propiedad física, geolocalizarla con coordenadas y subir imágenes a Cloudinary. | D28: Semana 6 | E28: Propiedades físicas (Accommodation) e imágenes Cloudinary | F28: 1 | G28: 9 | H28: SRP (IAccommodationService inventario físico), OCP/DIP (IImageStorageService desacoplado del proveedor cloud). | I28: F03 (Gestión de Al | P28: [====]
A29: Fase 5 | B29: Publicación y Catálogo Comercial (Listings) | C29: Objetivo: Implementar publicación de anuncios comerciales (AccommodationListing), buscador con filtros y mapas, y moderación admin. | Entregable: Propietario con >= 2 imágenes publica anuncio; tras aprobación admin entra en estado AVAILABLE en catálogo y mapa interactivo. | D29: Semana 7 | E29: Publicación comercial (AccommodationListing) y moderación | F29: 1 | G29: 12 | H29: SRP (IAccommodationListingService, IAccommodationReportService, IReviewService independientes). | I29: F03 (Alojamientos) | Q29: [====]
A30: Fase 6 | B30: Frontend Core (Desarrollo en Paralelo) | C30: Objetivo: Desarrollar la interfaz web completa para usuarios y administradores, consumiendo los endpoints REST de forma reactiva. | Entregable: Flujo visual y navegable completo de usuario y administrador en el frontend Next.js con Tailwind consumiendo Spring Boot. | D30: Semanas 6-7 | E30: Frontend Core (desarrollado en paralelo a Fases 4 y 5) | F30: 2 | G30: 11 | H30: Frontend-First, Zustand para autenticación, React Query para sincronización de servidor, componentes modulares. | I30: Transversal (Integ | P30: [====] | Q30: [====]
A31: Fase 7 | B31: Servidor MCP e Integración IA | C31: Objetivo: Construir el servidor MCP independiente y conectar la interfaz de chat del frontend para consultas en lenguaje natural. | Entregable: El usuario resuelve dudas ('¿Quién modificó el gasto?') mediante LLM llamando a herramientas MCP con seguridad multi-tenant. | D31: Semana 8 | E31: Servidor MCP e integración del chat IA | F31: 1 | G31: 12 | H31: Model Context Protocol (JSON-RPC 2.0), proxy autenticado sin almacenar tokens, esquemas Zod. | I31: F10 (Asistente Vir | R31: [====]
A32: Fase 8 | B32: Hardening, Documentación y Despliegue | C32: Objetivo: Preparar el proyecto para entrega académica con calidad de producción. | Entregable: Proyecto arranca con un único docker-compose up. Documentación OpenAPI en /swagger-ui.html y README completo. | D32: Semana 9 | E32: Hardening, documentación y despliegue | F32: 1 | G32: 15 | H32: Cobertura de tests >= 80%, perfiles Spring dev/prod, OpenAPI 3.0, CI/CD hardening. | I32: F01 (DevOps), F11 | S32: [====]
A33: TOTAL | B33: 9 Fases de Desarrollo | C33: Entorno arrancable, TDD obligatorio y documentación completa | D33: Semanas 0 a 9 | E33: Plan Teórico Base | F33: 10 | G33: 119 | H33: TDD y SOLID transversal | I33: Base de partida
A36: SECCIÓN 3: ANÁLISIS COMPARATIVO DIRECTO Y JUSTIFICACIONES TÉCNICAS (GAP ANALYSIS)
A37: Evaluación metodológica de las desviaciones temporales y justificación académica de la ampliación del alcance funcional (Scope Expansion).
A39: ID | B39: Módulo / Dimensión Evaluada | C39: Plan Teórico Estimado (CLAUDE.md) | F39: Ejecución Real (Repositorio / 42 PRs) | I39: Variación / Desviación | L39: Justificación Académica y Ampliación de Alcance para la Memoria del TFG
A40: C01 | B40: Horizonte Temporal y Esfuerzo Global | C40: 10 semanas estimadas (Semanas 0 a 9) con dedicación secuencial prevista. | F40: 16 semanas reales (113 días naturales: 01/06/2026 al 21/09/2026). 42 PRs aprobadas. | I40: +6 semanas (+60% de maduración temporal sobre la estimación inicial). | L40: La ampliación temporal responde a la transición de un prototipo monorepo básico hacia una plataforma completa con arquitectura limpia hexagonal, transacciones económicas seguras, empaquetado nativo para Android (Capacitor), gamificación de convivencia y cumplimiento estricto del RGPD europeo. Justifica con creces las ~300 horas correspondientes a los 12 créditos ECTS del TFG.
A41: C02 | B41: F01: Arquitectura Base, Infraestructura y DevOps | C41: Fase 0 (Semana 0) y Fase 8 (Semana 9): Scaffolding inicial y hardening final. | F41: Módulo transversal F01 (6 PRs: #1, #28, #35, #37, #41, #52) activo del 01/06 al 30/08 (91 días). | I41: Evolución continua de infraestructura a lo largo de todo el ciclo de vida. | L41: La infraestructura no fue un hito cerrado al inicio, sino una refactorización continua basada en principios SOLID: desacoplamiento de excepciones del dominio de la capa web, control de concurrencia con eventos de bloqueo transaccional y optimización de Docker Compose.
A42: C03 | B42: F02: Gestión de Usuarios, Autenticación y Perfiles | C42: Fase 1 (Semanas 1-2): Registro, login con JWT y perfil de usuario simple. | F42: Módulo F02 (10 PRs: #2, #3, #30, #31, #43, #46, #47, #48, #54, #60) de 28/06 a 04/09 (69 días). | I42: +5 semanas de desarrollo iterativo en seguridad, recuperación y ciclo de cuenta. | L42: Se amplió sustancialmente la seguridad mediante autenticación OAuth2 con Google, recuperación de contraseña tokenizada por correo, capa transversal de control de usuarios suspendidos/baneados (código HTTP 403 dinámico) y borrado lógico con derecho al olvido (soft delete).
A43: C04 | B43: F03: Gestión de Alojamientos y Catálogo | C43: Fases 4 y 5 (Semanas 6-7): Propiedades físicas, subida a Cloudinary y listings. | F43: Módulo F03 (6 PRs: #29, #33, #45, #49, #50, #55) de 05/07 a 30/08 (57 días). | I43: Desarrollo simultáneo y sincronizado de backend y frontend a lo largo de 8 semanas. | L43: Ampliación del catálogo con comodidades exclusivas de coliving, mapas interactivos con cálculo geoespacial de radio dinámico y un motor heurístico de recomendaciones personalizadas basado en el historial de búsquedas recientes del usuario.
A44: C05 | B44: F04: Solicitudes de Reserva y Pagos de Fianza | C44: Mencionado como submódulo simplificado contractual en Listings. | F44: Módulo independiente F04 (5 PRs: #32, #34, #36, #44, #51) de 13/07 a 30/08 (49 días). | I44: Creación de un dominio transaccional de alta complejidad no dimensionado en el plan. | L44: Implementación de máquina de estados determinista para reservas, validación estricta de meses de estancia para evitar solapamientos, tests de integración E2E, deep-linking y pasarela simulada de retención y liquidación de depósitos de fianza.
A45: C06 | B45: F05: Gestión de Hogares y Convivencia | C45: Fase 3 (Semana 5): Subsistema de auditoría inmutable append-only. | F45: Módulo F05 (3 PRs: #38, #40, #58) de 31/07 a 03/09 (35 días). | I45: Cohesión entre el espacio multi-tenant de coliving y la trazabilidad de eventos. | L45: Desarrollo del espacio multi-tenant del hogar compartido, gestión de convivientes condicionada a saldo cero y feed cronológico de eventos (Activity Log) desacoplado mediante formateo modular de estrategias.
A46: C07 | B46: F06: Gestión de Gastos Compartidos (Expenses) | C46: Fase 2 (Semanas 3-4): Motor financiero TDD de gastos y deudas simplificadas. | F46: Módulo F06 (2 PRs: #39, #59) de 07/08 a 03/09 (28 días). | I46: Ejecución rigurosa bajo TDD con posterior refinamiento funcional en septiembre. | L46: Implementación exitosa del algoritmo de simplificación de deudas en memoria mediante grafo de tránsito sin reescribir la BD, complementado posteriormente con liquidaciones de deuda parciales, edición de gastos y auditoría.
...

Sheet Gantt_Detalle_PRs
A1: COLIVI TFG - DETALLE DE PULL REQUESTS AGRUPADAS POR MÓDULO
A2: Desglose técnico de cada PR con su asignación a módulo funcional, rama, fechas de creación/merge y duración.
A4: WBS | B4: Módulo Funcional | C4: Nº PR | D4: Título de la PR | E4: Rama Origen | F4: Rama Destino | G4: Autor | H4: Aprobado Por | I4: Fecha Creación | J4: Fecha Merge | K4: Inicio (Gantt) | L4: Fin (Gantt) | M4: Duración (Días)
A5: F01 | B5: Arquitectura Base, Infraestructura y DevOps | C5: #1 | D5: Dev | E5: dev | F5: main | G5: vvu981 | H5: Merge Directo / Admin | I5: 2026-06-01 10:16 | J5: 2026-06-01 10:16 | K5: 46174 | L5: 46174 | M5: =L5-K5+1 -> 1
A6: F01 | B6: Arquitectura Base, Infraestructura y DevOps | C6: #28 | D6: Update GitHub CLI commands and fix Docker Compose issues | E6: feat/user | F6: dev | G6: vvu981 | H6: Merge Directo / Admin | I6: 2026-06-29 15:28 | J6: 2026-06-29 15:30 | K6: 46202 | L6: 46202 | M6: =L6-K6+1 -> 1
A7: F01 | B7: Arquitectura Base, Infraestructura y DevOps | C7: #35 | D7: refactor(core): decouple domain exceptions from web layer | E7: feat/solid-exceptions-refactor | F7: dev | G7: vvu981 | H7: Merge Directo / Admin | I7: 2026-07-15 12:38 | J7: 2026-07-15 12:41 | K7: 46218 | L7: 46218 | M7: =L7-K7+1 -> 1
A8: F01 | B8: Arquitectura Base, Infraestructura y DevOps | C8: #37 | D8: refactor: optimize core domains for SOLID, concurrency, and transactional consistency | E8: refactor/solid-events-lock | F8: dev | G8: vvu981 | H8: Merge Directo / Admin | I8: 2026-07-15 17:34 | J8: 2026-07-15 17:35 | K8: 46218 | L8: 46218 | M8: =L8-K8+1 -> 1
A9: F01 | B9: Arquitectura Base, Infraestructura y DevOps | C9: #41 | D9: Refactor/core architecture | E9: refactor/core-architecture | F9: dev | G9: vvu981 | H9: Merge Directo / Admin | I9: 2026-08-09 11:35 | J9: 2026-08-09 18:45 | K9: 46243 | L9: 46243 | M9: =L9-K9+1 -> 1
A10: F01 | B10: Arquitectura Base, Infraestructura y DevOps | C10: #52 | D10: Add 404 page and protect profile route | E10: feat/pageNotFound | F10: dev | G10: vvu981 | H10: Merge Directo / Admin | I10: 2026-08-30 15:01 | J10: 2026-08-30 15:01 | K10: 46264 | L10: 46264 | M10: =L10-K10+1 -> 1
A11: F02 | B11: Gestión de Usuarios, Autenticación y Perfiles | C11: #2 | D11: Refactor web layer and enforce DTO validation for user UUID | E11: feat/user | F11: dev | G11: vvu981 | H11: Merge Directo / Admin | I11: 2026-06-28 12:33 | J11: 2026-06-28 12:34 | K11: 46201 | L11: 46201 | M11: =L11-K11+1 -> 1
A12: F02 | B12: Gestión de Usuarios, Autenticación y Perfiles | C12: #3 | D12: Add email service and tests for user feature | E12: feat/user | F12: dev | G12: vvu981 | H12: Merge Directo / Admin | I12: 2026-06-29 12:08 | J12: 2026-06-29 12:11 | K12: 46202 | L12: 46202 | M12: =L12-K12+1 -> 1
A13: F02 | B13: Gestión de Usuarios, Autenticación y Perfiles | C13: #30 | D13: Fix/auth jwt banned 403 | E13: fix/auth-jwt-banned-403 | F13: dev | G13: vvu981 | H13: Merge Directo / Admin | I13: 2026-07-06 17:47 | J13: 2026-07-06 17:48 | K13: 46209 | L13: 46209 | M13: =L13-K13+1 -> 1
A14: F02 | B14: Gestión de Usuarios, Autenticación y Perfiles | C14: #31 | D14: feat(security): transversal user status enforcement layer | E14: fix/user-permissions | F14: dev | G14: vvu981 | H14: Merge Directo / Admin | I14: 2026-07-10 11:36 | J14: 2026-07-10 11:48 | K14: 46213 | L14: 46213 | M14: =L14-K14+1 -> 1
A15: F02 | B15: Gestión de Usuarios, Autenticación y Perfiles | C15: #43 | D15: Implement admin accommodation search and password recovery features | E15: feat/password-recovery-and-profiles | F15: dev | G15: vvu981 | H15: Merge Directo / Admin | I15: 2026-08-10 11:27 | J15: 2026-08-10 11:53 | K15: 46244 | L15: 46244 | M15: =L15-K15+1 -> 1
A16: F02 | B16: Gestión de Usuarios, Autenticación y Perfiles | C16: #46 | D16: feat(auth): implement Google Sign-in flow | E16: feat/frontend-layout | F16: dev | G16: vvu981 | H16: Merge Directo / Admin | I16: 2026-08-14 08:41 | J16: 2026-08-14 09:15 | K16: 46248 | L16: 46248 | M16: =L16-K16+1 -> 1
... A46: F12 | B46: Cumplimiento Legal y Privacidad (RGPD) | C46: #66 | D46: feat(compliance): add GDPR/LOPDGDD compliance layer with CMP, legal p… | E46: feat/terms | F46: dev | G46: vvu981 | H46: Merge Directo / Admin | I46: 2026-09-21 13:45 | J46: 2026-09-21 13:47 | K46: 46286 | L46: 46286 | M46: =L46-K46+1 -> 1
